<sdf version='1.7'>
  <world name='default'>
    <light name='sun' type='directional'>
      <cast_shadows>1</cast_shadows>
      <pose>0 0 10 0 -0 0</pose>
      <diffuse>0.8 0.8 0.8 1</diffuse>
      <specular>0.2 0.2 0.2 1</specular>
      <attenuation>
        <range>1000</range>
        <constant>0.9</constant>
        <linear>0.01</linear>
        <quadratic>0.001</quadratic>
      </attenuation>
      <direction>-0.5 0.1 -0.9</direction>
      <spot>
        <inner_angle>0</inner_angle>
        <outer_angle>0</outer_angle>
        <falloff>0</falloff>
      </spot>
    </light>
    <gravity>0 0 -9.8</gravity>
    <magnetic_field>6e-06 2.3e-05 -4.2e-05</magnetic_field>
    <atmosphere type='adiabatic'/>
    <physics type='ode'>
      <max_step_size>0.001</max_step_size>
      <real_time_factor>1</real_time_factor>
      <real_time_update_rate>1000</real_time_update_rate>
    </physics>
    <scene>
      <ambient>0.4 0.4 0.4 1</ambient>
      <background>0.7 0.7 0.7 1</background>
      <shadows>1</shadows>
    </scene>
    <wind/>
    <spherical_coordinates>
      <surface_model>EARTH_WGS84</surface_model>
      <latitude_deg>0</latitude_deg>
      <longitude_deg>0</longitude_deg>
      <elevation>0</elevation>
      <heading_deg>0</heading_deg>
    </spherical_coordinates>
    <model name='track'>
      <static>1</static>
      <link name='link'>
        <collision name='collision'>
          <geometry>
            <plane>
              <normal>0 0 1</normal>
              <size>14.68 14.99</size>
            </plane>
          </geometry>
          <surface>
            <contact>
              <collide_bitmask>65535</collide_bitmask>
              <ode/>
            </contact>
            <friction>
              <ode>
                <mu>1</mu>
                <mu2>1</mu2>
              </ode>
              <torsional>
                <ode/>
              </torsional>
            </friction>
            <bounce/>
          </surface>
          <max_contacts>10</max_contacts>
        </collision>
        <visual name='visual'>
          <cast_shadows>1</cast_shadows>
          <transparency>0</transparency>
          <geometry>
            <plane>
              <normal>0 0 1</normal>
              <size>14.68 14.99</size>
            </plane>
          </geometry>
          <material>
            <ambient>1 1 1 1</ambient>
            <diffuse>1 1 1 1</diffuse>
            <specular>0 0 0 0</specular>
            <emissive>1 1 1 1</emissive>
            <script>
              <uri>model://track/materials/scripts</uri>
              <uri>model://track/materials/textures</uri>
              <name>BFMC_MATERIAL</name>
            </script>
          </material>
        </visual>
        <self_collide>0</self_collide>
        <enable_wind>0</enable_wind>
        <kinematic>0</kinematic>
      </link>
      <pose>0.48212 -0.621388 0 0 -0 0</pose>
    </model>
    <model name='automobile'>
      <link name='chassis::link'>
        <inertial>
          <mass>0.26244</mass>
          <inertia>
            <ixx>0.00283444</ixx>
            <ixy>0</ixy>
            <ixz>0</ixz>
            <iyy>0.00039867</iyy>
            <iyz>0</iyz>
            <izz>0.00323293</izz>
          </inertia>
          <pose>0 0 0 0 -0 0</pose>
        </inertial>
        <pose>0 0 0 0 -0 1.5708</pose>
        <gravity>1</gravity>
        <kinematic>0</kinematic>
        <enable_wind>0</enable_wind>
        <self_collide>0</self_collide>
        <visual name='visual'>
          <pose>0 0 -0.0065 0 0 -1.57079</pose>
          <geometry>
            <mesh>
              <uri>model://chassis/meshes/chassisV5.dae</uri>
              <scale>1 1 1</scale>
            </mesh>
          </geometry>
          <material>
            <lighting>1</lighting>
            <shader type='vertex'>
              <normal_map>__default__</normal_map>
            </shader>
            <ambient>0.6 0.6 0.6 1</ambient>
            <diffuse>0.85 0.85 0.85 1</diffuse>
            <specular>0.6 0.6 0.6 1</specular>
            <emissive>0 0 0 1</emissive>
            <script>
              <name>ModelPreview_4::chassis::link::visual_MATERIAL_</name>
              <uri>__default__</uri>
            </script>
          </material>
          <transparency>0</transparency>
          <cast_shadows>1</cast_shadows>
        </visual>
        <collision name='collision'>
          <laser_retro>0</laser_retro>
          <max_contacts>10</max_contacts>
          <pose>0 0 0 0 -0 0</pose>
          <geometry>
            <box>
              <size>0.135 0.36 0.002</size>
            </box>
          </geometry>
          <surface>
            <friction>
              <ode>
                <mu>1</mu>
                <mu2>1</mu2>
                <fdir1>0 0 0</fdir1>
                <slip1>0</slip1>
                <slip2>0</slip2>
              </ode>
              <torsional>
                <coefficient>1</coefficient>
                <patch_radius>0</patch_radius>
                <surface_radius>0</surface_radius>
                <use_patch_radius>1</use_patch_radius>
                <ode>
                  <slip>0</slip>
                </ode>
              </torsional>
            </friction>
            <bounce>
              <restitution_coefficient>0</restitution_coefficient>
              <threshold>1e+06</threshold>
            </bounce>
            <contact>
              <collide_without_contact>0</collide_without_contact>
              <collide_without_contact_bitmask>1</collide_without_contact_bitmask>
              <collide_bitmask>1</collide_bitmask>
              <ode>
                <soft_cfm>0</soft_cfm>
                <soft_erp>0.2</soft_erp>
                <kp>1e+13</kp>
                <kd>1</kd>
                <max_vel>0.01</max_vel>
                <min_depth>0</min_depth>
              </ode>
              <bullet>
                <split_impulse>1</split_impulse>
                <split_impulse_penetration_threshold>-0.01</split_impulse_penetration_threshold>
                <soft_cfm>0</soft_cfm>
                <soft_erp>0.2</soft_erp>
                <kp>1e+13</kp>
                <kd>1</kd>
              </bullet>
            </contact>
          </surface>
        </collision>
      </link>
      <link name='cam_birdeye_REC::link_camera'>
        <inertial>
          <mass>0.001</mass>
          <inertia>
            <ixx>4.1e-07</ixx>
            <ixy>0</ixy>
            <ixz>0</ixz>
            <iyy>7.9e-07</iyy>
            <iyz>0</iyz>
            <izz>4.1e-07</izz>
          </inertia>
          <pose>0 0 0 0 -0 0</pose>
        </inertial>
        <pose>0 0 1.5 0 1.57079 0</pose>
        <gravity>1</gravity>
        <self_collide>0</self_collide>
        <kinematic>0</kinematic>
        <enable_wind>0</enable_wind>
        <sensor name='camera1' type='camera'>
          <update_rate>30</update_rate>
          <camera name='head'>
            <horizontal_fov>2</horizontal_fov>
            <image>
              <width>640</width>
              <height>480</height>
              <format>R8G8B8</format>
            </image>
            <clip>
              <near>0.02</near>
              <far>100</far>
            </clip>
            <noise>
              <type>gaussian</type>
              <mean>0</mean>
              <stddev>0</stddev>
            </noise>
          </camera>
          <plugin name='camera_controller' filename='libgazebo_ros_camera.so'>
            <alwaysOn>1</alwaysOn>
            <updateRate>0.0</updateRate>
            <cameraName>/rcCar/camera_birdeye</cameraName>
            <imageTopicName>image_raw</imageTopicName>
            <cameraInfoTopicName>camera_info</cameraInfoTopicName>
            <frameName>cam_birdeye_REC::link_camera</frameName>
            <ros>
              <namespace>camera</namespace>
              <!-- TODO(louise) Remapping not working due to https://github.com/ros-perception/image_common/issues/93 -->
              <remapping>image_raw:=image</remapping>
              <remapping>camera_info:=camera_info</remapping>
            </ros>
            <hackBaseline>0.0</hackBaseline>
            <distortionK1>0.0</distortionK1>
            <distortionK2>0.0</distortionK2>
            <distortionK3>0.0</distortionK3>
            <distortionT1>0.0</distortionT1>
            <distortionT2>0.0</distortionT2>
            <robotNamespace/>
          </plugin>
        </sensor>
        <visual name='visual'>
          <pose>0 0 0 0 -0 0</pose>
          <geometry>
            <box>
              <size>0.005 0.01 0.01</size>
            </box>
          </geometry>
          <material>
            <lighting>1</lighting>
            <script>
              <uri>file://media/materials/scripts/gazebo.material</uri>
              <name>Gazebo/Grey</name>
            </script>
            <shader type='vertex'>
              <normal_map>__default__</normal_map>
            </shader>
            <ambient>0.3 0.3 0.3 1</ambient>
            <diffuse>0.7 0.7 0.7 1</diffuse>
            <specular>0.01 0.01 0.01 1</specular>
            <emissive>0 0 0 1</emissive>
          </material>
          <transparency>0</transparency>
          <cast_shadows>1</cast_shadows>
        </visual>
        <collision name='collision'>
          <laser_retro>0</laser_retro>
          <max_contacts>10</max_contacts>
          <pose>0 0 0 0 -0 0</pose>
          <geometry>
            <box>
              <size>0.005 0.01 0.01</size>
            </box>
          </geometry>
          <surface>
            <friction>
              <ode>
                <mu>1</mu>
                <mu2>1</mu2>
                <fdir1>0 0 0</fdir1>
                <slip1>0</slip1>
                <slip2>0</slip2>
              </ode>
              <torsional>
                <coefficient>1</coefficient>
                <patch_radius>0</patch_radius>
                <surface_radius>0</surface_radius>
                <use_patch_radius>1</use_patch_radius>
                <ode>
                  <slip>0</slip>
                </ode>
              </torsional>
            </friction>
            <bounce>
              <restitution_coefficient>0</restitution_coefficient>
              <threshold>1e+06</threshold>
            </bounce>
            <contact>
              <collide_without_contact>0</collide_without_contact>
              <collide_without_contact_bitmask>1</collide_without_contact_bitmask>
              <collide_bitmask>1</collide_bitmask>
              <ode>
                <soft_cfm>0</soft_cfm>
                <soft_erp>0.2</soft_erp>
                <kp>1e+13</kp>
                <kd>1</kd>
                <max_vel>0.01</max_vel>
                <min_depth>0</min_depth>
              </ode>
              <bullet>
                <split_impulse>1</split_impulse>
                <split_impulse_penetration_threshold>-0.01</split_impulse_penetration_threshold>
                <soft_cfm>0</soft_cfm>
                <soft_erp>0.2</soft_erp>
                <kp>1e+13</kp>
                <kd>1</kd>
              </bullet>
            </contact>
          </surface>
        </collision>
      </link>
      <link name='camera::link_camera'>
        <inertial>
          <mass>0.0052875</mass>
          <inertia>
            <ixx>4.1e-07</ixx>
            <ixy>0</ixy>
            <ixz>0</ixz>
            <iyy>7.9e-07</iyy>
            <iyz>0</iyz>
            <izz>4.1e-07</izz>
          </inertia>
          <pose>0 0 0 0 -0 0</pose>
        </inertial>
        <pose>0 0 0.2 0 0.2617 0</pose>
        <gravity>1</gravity>
        <self_collide>0</self_collide>
        <kinematic>0</kinematic>
        <enable_wind>0</enable_wind>
        <sensor name='camera1' type='camera'>
          <update_rate>30</update_rate>
          <camera name='head'>
            <horizontal_fov>1.08559</horizontal_fov>
            <image>
              <width>640</width>
              <height>480</height>
              <format>R8G8B8</format>
            </image>
            <clip>
              <near>0.02</near>
              <far>100</far>
            </clip>
            <noise>
              <type>gaussian</type>
              <mean>0</mean>
              <stddev>0</stddev>
            </noise>
          </camera>
          <plugin name='camera_controller' filename='libgazebo_ros_camera.so'>
            <alwaysOn>1</alwaysOn>
            <updateRate>0.0</updateRate>
            <imageTopicName>image_raw</imageTopicName>
            <cameraInfoTopicName>camera_info</cameraInfoTopicName>
            <frameName>camera::link_camera</frameName>
            <ros>
              <namespace>camera_follow</namespace>
              <!-- TODO(louise) Remapping not working due to https://github.com/ros-perception/image_common/issues/93 -->
              <remapping>image_raw:=image</remapping>
              <remapping>camera_info:=camera_info</remapping>
            </ros>
            <hackBaseline>0.0</hackBaseline>
            <distortionK1>0.0</distortionK1>
            <distortionK2>0.0</distortionK2>
            <distortionK3>0.0</distortionK3>
            <distortionT1>0.0</distortionT1>
            <distortionT2>0.0</distortionT2>
            <robotNamespace/>
          </plugin>
        </sensor>
        <visual name='visual'>
          <pose>0 0 0 0 -0 0</pose>
          <geometry>
            <box>
              <size>0.005 0.03 0.03</size>
            </box>
          </geometry>
          <material>
            <lighting>1</lighting>
            <script>
              <uri>file://media/materials/scripts/gazebo.material</uri>
              <name>Gazebo/Grey</name>
            </script>
            <shader type='vertex'>
              <normal_map>__default__</normal_map>
            </shader>
            <ambient>0.3 0.3 0.3 1</ambient>
            <diffuse>0.7 0.7 0.7 1</diffuse>
            <specular>0.01 0.01 0.01 1</specular>
            <emissive>0 0 0 1</emissive>
          </material>
          <transparency>0</transparency>
          <cast_shadows>1</cast_shadows>
        </visual>
        <collision name='collision'>
          <laser_retro>0</laser_retro>
          <max_contacts>10</max_contacts>
          <pose>0 0 0 0 -0 0</pose>
          <geometry>
            <box>
              <size>0.005 0.03 0.03</size>
            </box>
          </geometry>
          <surface>
            <friction>
              <ode>
                <mu>1</mu>
                <mu2>1</mu2>
                <fdir1>0 0 0</fdir1>
                <slip1>0</slip1>
                <slip2>0</slip2>
              </ode>
              <torsional>
                <coefficient>1</coefficient>
                <patch_radius>0</patch_radius>
                <surface_radius>0</surface_radius>
                <use_patch_radius>1</use_patch_radius>
                <ode>
                  <slip>0</slip>
                </ode>
              </torsional>
            </friction>
            <bounce>
              <restitution_coefficient>0</restitution_coefficient>
              <threshold>1e+06</threshold>
            </bounce>
            <contact>
              <collide_without_contact>0</collide_without_contact>
              <collide_without_contact_bitmask>1</collide_without_contact_bitmask>
              <collide_bitmask>1</collide_bitmask>
              <ode>
                <soft_cfm>0</soft_cfm>
                <soft_erp>0.2</soft_erp>
                <kp>1e+13</kp>
                <kd>1</kd>
                <max_vel>0.01</max_vel>
                <min_depth>0</min_depth>
              </ode>
              <bullet>
                <split_impulse>1</split_impulse>
                <split_impulse_penetration_threshold>-0.01</split_impulse_penetration_threshold>
                <soft_cfm>0</soft_cfm>
                <soft_erp>0.2</soft_erp>
                <kp>1e+13</kp>
                <kd>1</kd>
              </bullet>
            </contact>
          </surface>
        </collision>
      </link>
      <link name='camera_follow::link_camera'>
        <inertial>
          <mass>0.001</mass>
          <inertia>
            <ixx>4.1e-07</ixx>
            <ixy>0</ixy>
            <ixz>0</ixz>
            <iyy>7.9e-07</iyy>
            <iyz>0</iyz>
            <izz>4.1e-07</izz>
          </inertia>
          <pose>0 0 0 0 -0 0</pose>
        </inertial>
        <pose>-0.3 0 0.45 0 0.6 0</pose>
        <gravity>1</gravity>
        <self_collide>0</self_collide>
        <kinematic>0</kinematic>
        <enable_wind>0</enable_wind>
        <sensor name='camera1' type='camera'>
          <update_rate>30</update_rate>
          <camera name='head'>
            <horizontal_fov>1.3708</horizontal_fov>
            <image>
              <width>1920</width>
              <height>1080</height>
              <format>R8G8B8</format>
            </image>
            <clip>
              <near>0.02</near>
              <far>100</far>
            </clip>
            <noise>
              <type>gaussian</type>
              <mean>0</mean>
              <stddev>0</stddev>
            </noise>
          </camera>
          <plugin name='camera_controller' filename='libgazebo_ros_camera.so'>
            <alwaysOn>1</alwaysOn>
            <updateRate>0.0</updateRate>
            <cameraName>/rcCar/camera_follow</cameraName>
            <imageTopicName>image_raw</imageTopicName>
            <cameraInfoTopicName>camera_info</cameraInfoTopicName>
            <frameName>camera_follow::link_camera</frameName>
            <ros>
              <namespace>camera_birdeye</namespace>
              <!-- TODO(louise) Remapping not working due to https://github.com/ros-perception/image_common/issues/93 -->
              <remapping>image_raw:=image</remapping>
              <remapping>camera_info:=camera_info</remapping>
            </ros>
            <hackBaseline>0.0</hackBaseline>
            <distortionK1>0.0</distortionK1>
            <distortionK2>0.0</distortionK2>
            <distortionK3>0.0</distortionK3>
            <distortionT1>0.0</distortionT1>
            <distortionT2>0.0</distortionT2>
            <robotNamespace/>
          </plugin>
        </sensor>
        <visual name='visual'>
          <pose>0 0 0 0 -0 0</pose>
          <geometry>
            <box>
              <size>0.005 0.01 0.01</size>
            </box>
          </geometry>
          <material>
            <lighting>1</lighting>
            <script>
              <uri>file://media/materials/scripts/gazebo.material</uri>
              <name>Gazebo/Grey</name>
            </script>
            <shader type='vertex'>
              <normal_map>__default__</normal_map>
            </shader>
            <ambient>0.3 0.3 0.3 1</ambient>
            <diffuse>0.7 0.7 0.7 1</diffuse>
            <specular>0.01 0.01 0.01 1</specular>
            <emissive>0 0 0 1</emissive>
          </material>
          <transparency>0</transparency>
          <cast_shadows>1</cast_shadows>
        </visual>
        <collision name='collision'>
          <laser_retro>0</laser_retro>
          <max_contacts>10</max_contacts>
          <pose>0 0 0 0 -0 0</pose>
          <geometry>
            <box>
              <size>0.005 0.01 0.01</size>
            </box>
          </geometry>
          <surface>
            <friction>
              <ode>
                <mu>1</mu>
                <mu2>1</mu2>
                <fdir1>0 0 0</fdir1>
                <slip1>0</slip1>
                <slip2>0</slip2>
              </ode>
              <torsional>
                <coefficient>1</coefficient>
                <patch_radius>0</patch_radius>
                <surface_radius>0</surface_radius>
                <use_patch_radius>1</use_patch_radius>
                <ode>
                  <slip>0</slip>
                </ode>
              </torsional>
            </friction>
            <bounce>
              <restitution_coefficient>0</restitution_coefficient>
              <threshold>1e+06</threshold>
            </bounce>
            <contact>
              <collide_without_contact>0</collide_without_contact>
              <collide_without_contact_bitmask>1</collide_without_contact_bitmask>
              <collide_bitmask>1</collide_bitmask>
              <ode>
                <soft_cfm>0</soft_cfm>
                <soft_erp>0.2</soft_erp>
                <kp>1e+13</kp>
                <kd>1</kd>
                <max_vel>0.01</max_vel>
                <min_depth>0</min_depth>
              </ode>
              <bullet>
                <split_impulse>1</split_impulse>
                <split_impulse_penetration_threshold>-0.01</split_impulse_penetration_threshold>
                <soft_cfm>0</soft_cfm>
                <soft_erp>0.2</soft_erp>
                <kp>1e+13</kp>
                <kd>1</kd>
              </bullet>
            </contact>
          </surface>
        </collision>
      </link>
      <link name='car_body::link'>
        <inertial>
          <mass>1</mass>
          <inertia>
            <ixx>0.166667</ixx>
            <ixy>0</ixy>
            <ixz>0</ixz>
            <iyy>0.166667</iyy>
            <iyz>0</iyz>
            <izz>0.166667</izz>
          </inertia>
          <pose>0 0 0 0 -0 0</pose>
        </inertial>
        <pose>-0.024 0 -0.028 0 -0 0</pose>
        <self_collide>0</self_collide>
        <enable_wind>0</enable_wind>
        <kinematic>0</kinematic>
        <visual name='visual'>
          <pose>0 0 0 0 -0 0</pose>
          <geometry>
            <mesh>
              <uri>model://car_body/meshes/CarBody.dae</uri>
              <scale>1 1 1</scale>
            </mesh>
          </geometry>
          <material>
            <script>
              <uri>model://car_body/materials/scripts</uri>
              <uri>model://car_body/materials/textures</uri>
              <name>CarBody/Image</name>
            </script>
            <shader type='pixel'/>
          </material>
          <transparency>0</transparency>
          <cast_shadows>1</cast_shadows>
        </visual>
      </link>
      <link name='steer_left::link_steer'>
        <inertial>
          <mass>0.001</mass>
          <inertia>
            <ixx>0.00014583</ixx>
            <ixy>0</ixy>
            <ixz>0</ixz>
            <iyy>0.00014583</iyy>
            <iyz>0</iyz>
            <izz>0.000125</izz>
          </inertia>
          <pose>0 0 0 0 -0 0</pose>
        </inertial>
        <pose>0.112 0.0725 0 1.5708 -0 0</pose>
        <gravity>1</gravity>
        <self_collide>0</self_collide>
        <kinematic>0</kinematic>
        <enable_wind>0</enable_wind>
        <visual name='visual'>
          <pose>0 0 0 0 -0 0</pose>
          <geometry>
            <cylinder>
              <radius>0.001</radius>
              <length>0.01</length>
            </cylinder>
          </geometry>
          <material>
            <lighting>1</lighting>
            <script>
              <uri>file://media/materials/scripts/gazebo.material</uri>
              <name>Gazebo/Grey</name>
            </script>
            <shader type='vertex'>
              <normal_map>__default__</normal_map>
            </shader>
            <ambient>0.3 0.3 0.3 1</ambient>
            <diffuse>0.7 0.7 0.7 1</diffuse>
            <specular>0.01 0.01 0.01 1</specular>
            <emissive>0 0 0 1</emissive>
          </material>
          <transparency>0</transparency>
          <cast_shadows>1</cast_shadows>
        </visual>
        <collision name='collision'>
          <laser_retro>0</laser_retro>
          <max_contacts>10</max_contacts>
          <pose>0 0 0 0 -0 0</pose>
          <geometry>
            <cylinder>
              <radius>0.001</radius>
              <length>0.01</length>
            </cylinder>
          </geometry>
          <surface>
            <friction>
              <ode>
                <mu>1</mu>
                <mu2>1</mu2>
                <fdir1>0 0 0</fdir1>
                <slip1>0</slip1>
                <slip2>0</slip2>
              </ode>
              <torsional>
                <coefficient>1</coefficient>
                <patch_radius>0</patch_radius>
                <surface_radius>0</surface_radius>
                <use_patch_radius>1</use_patch_radius>
                <ode>
                  <slip>0</slip>
                </ode>
              </torsional>
            </friction>
            <bounce>
              <restitution_coefficient>0</restitution_coefficient>
              <threshold>1e+06</threshold>
            </bounce>
            <contact>
              <collide_without_contact>0</collide_without_contact>
              <collide_without_contact_bitmask>1</collide_without_contact_bitmask>
              <collide_bitmask>1</collide_bitmask>
              <ode>
                <soft_cfm>0</soft_cfm>
                <soft_erp>0.2</soft_erp>
                <kp>1e+13</kp>
                <kd>1</kd>
                <max_vel>0.01</max_vel>
                <min_depth>0</min_depth>
              </ode>
              <bullet>
                <split_impulse>1</split_impulse>
                <split_impulse_penetration_threshold>-0.01</split_impulse_penetration_threshold>
                <soft_cfm>0</soft_cfm>
                <soft_erp>0.2</soft_erp>
                <kp>1e+13</kp>
                <kd>1</kd>
              </bullet>
            </contact>
          </surface>
        </collision>
      </link>
      <link name='steer_right::link_steer'>
        <inertial>
          <mass>0.001</mass>
          <inertia>
            <ixx>0.00014583</ixx>
            <ixy>0</ixy>
            <ixz>0</ixz>
            <iyy>0.00014583</iyy>
            <iyz>0</iyz>
            <izz>0.000125</izz>
          </inertia>
          <pose>0 0 0 0 -0 0</pose>
        </inertial>
        <pose>0.112 -0.0725 0 1.5708 -0 0</pose>
        <gravity>1</gravity>
        <self_collide>0</self_collide>
        <kinematic>0</kinematic>
        <enable_wind>0</enable_wind>
        <visual name='visual'>
          <pose>0 0 0 0 -0 0</pose>
          <geometry>
            <cylinder>
              <radius>0.001</radius>
              <length>0.01</length>
            </cylinder>
          </geometry>
          <material>
            <lighting>1</lighting>
            <script>
              <uri>file://media/materials/scripts/gazebo.material</uri>
              <name>Gazebo/Grey</name>
            </script>
            <shader type='vertex'>
              <normal_map>__default__</normal_map>
            </shader>
            <ambient>0.3 0.3 0.3 1</ambient>
            <diffuse>0.7 0.7 0.7 1</diffuse>
            <specular>0.01 0.01 0.01 1</specular>
            <emissive>0 0 0 1</emissive>
          </material>
          <transparency>0</transparency>
          <cast_shadows>1</cast_shadows>
        </visual>
        <collision name='collision'>
          <laser_retro>0</laser_retro>
          <max_contacts>10</max_contacts>
          <pose>0 0 0 0 -0 0</pose>
          <geometry>
            <cylinder>
              <radius>0.001</radius>
              <length>0.01</length>
            </cylinder>
          </geometry>
          <surface>
            <friction>
              <ode>
                <mu>1</mu>
                <mu2>1</mu2>
                <fdir1>0 0 0</fdir1>
                <slip1>0</slip1>
                <slip2>0</slip2>
              </ode>
              <torsional>
                <coefficient>1</coefficient>
                <patch_radius>0</patch_radius>
                <surface_radius>0</surface_radius>
                <use_patch_radius>1</use_patch_radius>
                <ode>
                  <slip>0</slip>
                </ode>
              </torsional>
            </friction>
            <bounce>
              <restitution_coefficient>0</restitution_coefficient>
              <threshold>1e+06</threshold>
            </bounce>
            <contact>
              <collide_without_contact>0</collide_without_contact>
              <collide_without_contact_bitmask>1</collide_without_contact_bitmask>
              <collide_bitmask>1</collide_bitmask>
              <ode>
                <soft_cfm>0</soft_cfm>
                <soft_erp>0.2</soft_erp>
                <kp>1e+13</kp>
                <kd>1</kd>
                <max_vel>0.01</max_vel>
                <min_depth>0</min_depth>
              </ode>
              <bullet>
                <split_impulse>1</split_impulse>
                <split_impulse_penetration_threshold>-0.01</split_impulse_penetration_threshold>
                <soft_cfm>0</soft_cfm>
                <soft_erp>0.2</soft_erp>
                <kp>1e+13</kp>
                <kd>1</kd>
              </bullet>
            </contact>
          </surface>
        </collision>
      </link>
      <link name='wheel_front_left::link_rim'>
        <inertial>
          <mass>0.038</mass>
          <inertia>
            <ixx>1.283e-05</ixx>
            <ixy>0</ixy>
            <ixz>0</ixz>
            <iyy>1.283e-05</iyy>
            <iyz>0</iyz>
            <izz>2.069e-05</izz>
          </inertia>
          <pose>0 0 0 0 -0 0</pose>
        </inertial>
        <pose>0.118 0.081 0 1.5708 -0 0</pose>
        <gravity>1</gravity>
        <kinematic>0</kinematic>
        <enable_wind>0</enable_wind>
        <self_collide>0</self_collide>
        <visual name='visual'>
          <pose>0 0 0 -1.5708 0 0</pose>
          <geometry>
            <mesh>
              <uri>model://wheel_left/meshes/rim.dae</uri>
              <scale>1 1 1</scale>
            </mesh>
          </geometry>
          <material>
            <lighting>1</lighting>
            <shader type='vertex'>
              <normal_map>__default__</normal_map>
            </shader>
            <ambient>0.2 0.2 0.2 1</ambient>
            <diffuse>0.3 0.3 0.3 1</diffuse>
            <specular>0.5 0.5 0.5 1</specular>
            <emissive>0 0 0 0</emissive>
            <script>
              <name>ModelPreview_4::wheel_front_left::link_rim::visual_MATERIAL_</name>
              <uri>__default__</uri>
            </script>
          </material>
          <transparency>0</transparency>
          <cast_shadows>1</cast_shadows>
        </visual>
        <collision name='collision'>
          <laser_retro>0</laser_retro>
          <max_contacts>10</max_contacts>
          <pose>0 0 0 0 -0 0</pose>
          <geometry>
            <cylinder>
              <radius>0.033</radius>
              <length>0.028</length>
            </cylinder>
          </geometry>
          <surface>
            <friction>
              <ode>
                <mu>0.7</mu>
                <mu2>0.7</mu2>
                <fdir1>0 0 0</fdir1>
                <slip1>0</slip1>
                <slip2>0</slip2>
              </ode>
              <torsional>
                <coefficient>1</coefficient>
                <patch_radius>0</patch_radius>
                <surface_radius>0</surface_radius>
                <use_patch_radius>1</use_patch_radius>
                <ode>
                  <slip>0</slip>
                </ode>
              </torsional>
            </friction>
            <bounce>
              <restitution_coefficient>0</restitution_coefficient>
              <threshold>1e+06</threshold>
            </bounce>
            <contact>
              <collide_without_contact>0</collide_without_contact>
              <collide_without_contact_bitmask>1</collide_without_contact_bitmask>
              <collide_bitmask>1</collide_bitmask>
              <ode>
                <soft_cfm>0</soft_cfm>
                <soft_erp>0.2</soft_erp>
                <kp>1e+07</kp>
                <kd>1</kd>
                <max_vel>0.01</max_vel>
                <min_depth>0</min_depth>
              </ode>
              <bullet>
                <split_impulse>1</split_impulse>
                <split_impulse_penetration_threshold>-0.01</split_impulse_penetration_threshold>
                <soft_cfm>0</soft_cfm>
                <soft_erp>0.2</soft_erp>
                <kp>1e+07</kp>
                <kd>1</kd>
              </bullet>
            </contact>
          </surface>
        </collision>
      </link>
      <link name='wheel_front_right::link_rim'>
        <inertial>
          <mass>0.038</mass>
          <inertia>
            <ixx>1.283e-05</ixx>
            <ixy>0</ixy>
            <ixz>0</ixz>
            <iyy>1.283e-05</iyy>
            <iyz>0</iyz>
            <izz>2.069e-05</izz>
          </inertia>
          <pose>0 0 0 0 -0 0</pose>
        </inertial>
        <pose>0.118 -0.081 0 1.5708 -0 0</pose>
        <gravity>1</gravity>
        <kinematic>0</kinematic>
        <enable_wind>0</enable_wind>
        <self_collide>0</self_collide>
        <visual name='visual'>
          <pose>0 0 0 -1.5708 0 0</pose>
          <geometry>
            <mesh>
              <uri>model://wheel_right/meshes/rim.dae</uri>
              <scale>1 1 1</scale>
            </mesh>
          </geometry>
          <material>
            <lighting>1</lighting>
            <shader type='vertex'>
              <normal_map>__default__</normal_map>
            </shader>
            <ambient>0.2 0.2 0.2 1</ambient>
            <diffuse>0.3 0.3 0.3 1</diffuse>
            <specular>0.5 0.5 0.5 1</specular>
            <emissive>0 0 0 0</emissive>
            <script>
              <name>ModelPreview_4::wheel_front_right::link_rim::visual_MATERIAL_</name>
              <uri>__default__</uri>
            </script>
          </material>
          <transparency>0</transparency>
          <cast_shadows>1</cast_shadows>
        </visual>
        <collision name='collision'>
          <laser_retro>0</laser_retro>
          <max_contacts>10</max_contacts>
          <pose>0 0 0 0 -0 0</pose>
          <geometry>
            <cylinder>
              <radius>0.033</radius>
              <length>0.028</length>
            </cylinder>
          </geometry>
          <surface>
            <friction>
              <ode>
                <mu>0.7</mu>
                <mu2>0.7</mu2>
                <fdir1>0 0 0</fdir1>
                <slip1>0</slip1>
                <slip2>0</slip2>
              </ode>
              <torsional>
                <coefficient>1</coefficient>
                <patch_radius>0</patch_radius>
                <surface_radius>0</surface_radius>
                <use_patch_radius>1</use_patch_radius>
                <ode>
                  <slip>0</slip>
                </ode>
              </torsional>
            </friction>
            <bounce>
              <restitution_coefficient>0</restitution_coefficient>
              <threshold>1e+06</threshold>
            </bounce>
            <contact>
              <collide_without_contact>0</collide_without_contact>
              <collide_without_contact_bitmask>1</collide_without_contact_bitmask>
              <collide_bitmask>1</collide_bitmask>
              <ode>
                <soft_cfm>0</soft_cfm>
                <soft_erp>0.2</soft_erp>
                <kp>1e+07</kp>
                <kd>1</kd>
                <max_vel>0.01</max_vel>
                <min_depth>0</min_depth>
              </ode>
              <bullet>
                <split_impulse>1</split_impulse>
                <split_impulse_penetration_threshold>-0.01</split_impulse_penetration_threshold>
                <soft_cfm>0</soft_cfm>
                <soft_erp>0.2</soft_erp>
                <kp>1e+07</kp>
                <kd>1</kd>
              </bullet>
            </contact>
          </surface>
        </collision>
      </link>
      <link name='wheel_rear_left::link_rim'>
        <inertial>
          <mass>0.038</mass>
          <inertia>
            <ixx>1.283e-05</ixx>
            <ixy>0</ixy>
            <ixz>0</ixz>
            <iyy>1.283e-05</iyy>
            <iyz>0</iyz>
            <izz>2.069e-05</izz>
          </inertia>
          <pose>0 0 0 0 -0 0</pose>
        </inertial>
        <pose>-0.152 0.081 0 1.5708 -0 0</pose>
        <gravity>1</gravity>
        <kinematic>0</kinematic>
        <enable_wind>0</enable_wind>
        <self_collide>0</self_collide>
        <visual name='visual'>
          <pose>0 0 0 -1.5708 0 0</pose>
          <geometry>
            <mesh>
              <uri>model://wheel_left/meshes/rim.dae</uri>
              <scale>1 1 1</scale>
            </mesh>
          </geometry>
          <material>
            <lighting>1</lighting>
            <shader type='vertex'>
              <normal_map>__default__</normal_map>
            </shader>
            <ambient>0.2 0.2 0.2 1</ambient>
            <diffuse>0.3 0.3 0.3 1</diffuse>
            <specular>0.5 0.5 0.5 1</specular>
            <emissive>0 0 0 0</emissive>
            <script>
              <name>ModelPreview_4::wheel_rear_left::link_rim::visual_MATERIAL_</name>
              <uri>__default__</uri>
            </script>
          </material>
          <transparency>0</transparency>
          <cast_shadows>1</cast_shadows>
        </visual>
        <collision name='collision'>
          <laser_retro>0</laser_retro>
          <max_contacts>10</max_contacts>
          <pose>0 0 0 0 -0 0</pose>
          <geometry>
            <cylinder>
              <radius>0.033</radius>
              <length>0.028</length>
            </cylinder>
          </geometry>
          <surface>
            <friction>
              <ode>
                <mu>0.7</mu>
                <mu2>0.7</mu2>
                <fdir1>0 0 0</fdir1>
                <slip1>0</slip1>
                <slip2>0</slip2>
              </ode>
              <torsional>
                <coefficient>1</coefficient>
                <patch_radius>0</patch_radius>
                <surface_radius>0</surface_radius>
                <use_patch_radius>1</use_patch_radius>
                <ode>
                  <slip>0</slip>
                </ode>
              </torsional>
            </friction>
            <bounce>
              <restitution_coefficient>0</restitution_coefficient>
              <threshold>1e+06</threshold>
            </bounce>
            <contact>
              <collide_without_contact>0</collide_without_contact>
              <collide_without_contact_bitmask>1</collide_without_contact_bitmask>
              <collide_bitmask>1</collide_bitmask>
              <ode>
                <soft_cfm>0</soft_cfm>
                <soft_erp>0.2</soft_erp>
                <kp>1e+07</kp>
                <kd>1</kd>
                <max_vel>0.01</max_vel>
                <min_depth>0</min_depth>
              </ode>
              <bullet>
                <split_impulse>1</split_impulse>
                <split_impulse_penetration_threshold>-0.01</split_impulse_penetration_threshold>
                <soft_cfm>0</soft_cfm>
                <soft_erp>0.2</soft_erp>
                <kp>1e+07</kp>
                <kd>1</kd>
              </bullet>
            </contact>
          </surface>
        </collision>
      </link>
      <link name='wheel_rear_right::link_rim'>
        <inertial>
          <mass>0.038</mass>
          <inertia>
            <ixx>1.283e-05</ixx>
            <ixy>0</ixy>
            <ixz>0</ixz>
            <iyy>1.283e-05</iyy>
            <iyz>0</iyz>
            <izz>2.069e-05</izz>
          </inertia>
          <pose>0 0 0 0 -0 0</pose>
        </inertial>
        <pose>-0.152 -0.081 0 1.5708 -0 0</pose>
        <gravity>1</gravity>
        <kinematic>0</kinematic>
        <enable_wind>0</enable_wind>
        <self_collide>0</self_collide>
        <visual name='visual'>
          <pose>0 0 0 -1.5708 0 0</pose>
          <geometry>
            <mesh>
              <uri>model://wheel_right/meshes/rim.dae</uri>
              <scale>1 1 1</scale>
            </mesh>
          </geometry>
          <material>
            <lighting>1</lighting>
            <shader type='vertex'>
              <normal_map>__default__</normal_map>
            </shader>
            <ambient>0.2 0.2 0.2 1</ambient>
            <diffuse>0.3 0.3 0.3 1</diffuse>
            <specular>0.5 0.5 0.5 1</specular>
            <emissive>0 0 0 0</emissive>
            <script>
              <name>ModelPreview_4::wheel_rear_right::link_rim::visual_MATERIAL_</name>
              <uri>__default__</uri>
            </script>
          </material>
          <transparency>0</transparency>
          <cast_shadows>1</cast_shadows>
        </visual>
        <collision name='collision'>
          <laser_retro>0</laser_retro>
          <max_contacts>10</max_contacts>
          <pose>0 0 0 0 -0 0</pose>
          <geometry>
            <cylinder>
              <radius>0.033</radius>
              <length>0.028</length>
            </cylinder>
          </geometry>
          <surface>
            <friction>
              <ode>
                <mu>0.7</mu>
                <mu2>0.7</mu2>
                <fdir1>0 0 0</fdir1>
                <slip1>0</slip1>
                <slip2>0</slip2>
              </ode>
              <torsional>
                <coefficient>1</coefficient>
                <patch_radius>0</patch_radius>
                <surface_radius>0</surface_radius>
                <use_patch_radius>1</use_patch_radius>
                <ode>
                  <slip>0</slip>
                </ode>
              </torsional>
            </friction>
            <bounce>
              <restitution_coefficient>0</restitution_coefficient>
              <threshold>1e+06</threshold>
            </bounce>
            <contact>
              <collide_without_contact>0</collide_without_contact>
              <collide_without_contact_bitmask>1</collide_without_contact_bitmask>
              <collide_bitmask>1</collide_bitmask>
              <ode>
                <soft_cfm>0</soft_cfm>
                <soft_erp>0.2</soft_erp>
                <kp>1e+07</kp>
                <kd>1</kd>
                <max_vel>0.01</max_vel>
                <min_depth>0</min_depth>
              </ode>
              <bullet>
                <split_impulse>1</split_impulse>
                <split_impulse_penetration_threshold>-0.01</split_impulse_penetration_threshold>
                <soft_cfm>0</soft_cfm>
                <soft_erp>0.2</soft_erp>
                <kp>1e+07</kp>
                <kd>1</kd>
              </bullet>
            </contact>
          </surface>
        </collision>
      </link>
      <joint name='joint_body' type='fixed'>
        <parent>chassis::link</parent>
        <child>car_body::link</child>
        <pose>0 0 0 0 -0 0</pose>
        <physics>
          <ode>
            <limit>
              <cfm>0</cfm>
              <erp>0.2</erp>
            </limit>
            <suspension>
              <cfm>0</cfm>
              <erp>0.2</erp>
            </suspension>
          </ode>
        </physics>
      </joint>
      <joint name='joint_cam_birdeye_REC' type='fixed'>
        <parent>chassis::link</parent>
        <child>cam_birdeye_REC::link_camera</child>
        <pose>0 0 0 0 -0 0</pose>
        <physics>
          <ode>
            <limit>
              <cfm>0</cfm>
              <erp>0.2</erp>
            </limit>
            <suspension>
              <cfm>0</cfm>
              <erp>0.2</erp>
            </suspension>
          </ode>
        </physics>
      </joint>
      <joint name='joint_camera' type='fixed'>
        <parent>chassis::link</parent>
        <child>camera::link_camera</child>
        <pose>0 0 0 0 -0 0</pose>
        <physics>
          <ode>
            <limit>
              <cfm>0</cfm>
              <erp>0.2</erp>
            </limit>
            <suspension>
              <cfm>0</cfm>
              <erp>0.2</erp>
            </suspension>
          </ode>
        </physics>
      </joint>
      <joint name='joint_camera_follow' type='fixed'>
        <parent>chassis::link</parent>
        <child>camera_follow::link_camera</child>
        <pose>0 0 0 0 -0 0</pose>
        <physics>
          <ode>
            <limit>
              <cfm>0</cfm>
              <erp>0.2</erp>
            </limit>
            <suspension>
              <cfm>0</cfm>
              <erp>0.2</erp>
            </suspension>
          </ode>
        </physics>
      </joint>
      <joint name='joint_leftfront_rim' type='revolute'>
        <parent>steer_left::link_steer</parent>
        <child>wheel_front_left::link_rim</child>
        <pose>0 0 0 0 -0 0</pose>
        <axis>
          <xyz>0 0 -1</xyz>
          <limit>
            <lower>-1.79769e+308</lower>
            <upper>1.79769e+308</upper>
            <effort>-1</effort>
            <velocity>-1</velocity>
          </limit>
          <dynamics>
            <spring_reference>0</spring_reference>
            <spring_stiffness>0</spring_stiffness>
            <damping>0</damping>
            <friction>0</friction>
          </dynamics>
        </axis>
        <physics>
          <ode>
            <limit>
              <cfm>0</cfm>
              <erp>0.2</erp>
            </limit>
            <suspension>
              <cfm>0</cfm>
              <erp>0.2</erp>
            </suspension>
          </ode>
        </physics>
      </joint>
      <joint name='joint_leftfront_steer' type='revolute'>
        <parent>chassis::link</parent>
        <child>steer_left::link_steer</child>
        <pose>0 0 0.005 0 -0 0</pose>
        <axis>
          <xyz>0 1 0</xyz>
          <limit>
            <lower>-1.79769e+308</lower>
            <upper>1.79769e+308</upper>
            <effort>-1</effort>
            <velocity>-1</velocity>
          </limit>
          <dynamics>
            <spring_reference>0</spring_reference>
            <spring_stiffness>0</spring_stiffness>
            <damping>0</damping>
            <friction>0</friction>
          </dynamics>
        </axis>
        <physics>
          <ode>
            <limit>
              <cfm>0</cfm>
              <erp>0.2</erp>
            </limit>
            <suspension>
              <cfm>0</cfm>
              <erp>0.2</erp>
            </suspension>
          </ode>
        </physics>
      </joint>
      <joint name='joint_leftrear_rim' type='revolute'>
        <parent>chassis::link</parent>
        <child>wheel_rear_left::link_rim</child>
        <pose>0 0 0 0 -0 0</pose>
        <axis>
          <xyz>0 0 -1</xyz>
          <limit>
            <lower>-1.79769e+308</lower>
            <upper>1.79769e+308</upper>
            <effort>-1</effort>
            <velocity>-1</velocity>
          </limit>
          <dynamics>
            <spring_reference>0</spring_reference>
            <spring_stiffness>0</spring_stiffness>
            <damping>0</damping>
            <friction>0</friction>
          </dynamics>
        </axis>
        <physics>
          <ode>
            <limit>
              <cfm>0</cfm>
              <erp>0.2</erp>
            </limit>
            <suspension>
              <cfm>0</cfm>
              <erp>0.2</erp>
            </suspension>
          </ode>
        </physics>
      </joint>
      <joint name='joint_rightfront_rim' type='revolute'>
        <parent>steer_right::link_steer</parent>
        <child>wheel_front_right::link_rim</child>
        <pose>0 0 0 0 -0 0</pose>
        <axis>
          <xyz>0 0 -1</xyz>
          <limit>
            <lower>-1.79769e+308</lower>
            <upper>1.79769e+308</upper>
            <effort>-1</effort>
            <velocity>-1</velocity>
          </limit>
          <dynamics>
            <spring_reference>0</spring_reference>
            <spring_stiffness>0</spring_stiffness>
            <damping>0</damping>
            <friction>0</friction>
          </dynamics>
        </axis>
        <physics>
          <ode>
            <limit>
              <cfm>0</cfm>
              <erp>0.2</erp>
            </limit>
            <suspension>
              <cfm>0</cfm>
              <erp>0.2</erp>
            </suspension>
          </ode>
        </physics>
      </joint>
      <joint name='joint_rightfront_steer' type='revolute'>
        <parent>chassis::link</parent>
        <child>steer_right::link_steer</child>
        <pose>0 0 -0.005 0 -0 0</pose>
        <axis>
          <xyz>0 1 0</xyz>
          <limit>
            <lower>-1.79769e+308</lower>
            <upper>1.79769e+308</upper>
            <effort>-1</effort>
            <velocity>-1</velocity>
          </limit>
          <dynamics>
            <spring_reference>0</spring_reference>
            <spring_stiffness>0</spring_stiffness>
            <damping>0</damping>
            <friction>0</friction>
          </dynamics>
        </axis>
        <physics>
          <ode>
            <limit>
              <cfm>0</cfm>
              <erp>0.2</erp>
            </limit>
            <suspension>
              <cfm>0</cfm>
              <erp>0.2</erp>
            </suspension>
          </ode>
        </physics>
      </joint>
      <joint name='joint_rightrear_rim' type='revolute'>
        <parent>chassis::link</parent>
        <child>wheel_rear_right::link_rim</child>
        <pose>0 0 0 0 -0 0</pose>
        <axis>
          <xyz>0 0 -1</xyz>
          <limit>
            <lower>-1.79769e+308</lower>
            <upper>1.79769e+308</upper>
            <effort>-1</effort>
            <velocity>-1</velocity>
          </limit>
          <dynamics>
            <spring_reference>0</spring_reference>
            <spring_stiffness>0</spring_stiffness>
            <damping>0</damping>
            <friction>0</friction>
          </dynamics>
        </axis>
        <physics>
          <ode>
            <limit>
              <cfm>0</cfm>
              <erp>0.2</erp>
            </limit>
            <suspension>
              <cfm>0</cfm>
              <erp>0.2</erp>
            </suspension>
          </ode>
        </physics>
      </joint>
      <static>0</static>
      <allow_auto_disable>1</allow_auto_disable>
      <plugin name='omni_steering' filename='libgazebo_ros_planar_move.so'>
        <commandTopic>cmd_vel</commandTopic>
        <odometryTopic>odom</odometryTopic>
        <odometryFrame>odom</odometryFrame>
        <odometryRate>100</odometryRate>
        <robotBaseFrame>chassis</robotBaseFrame>
        <publishTF>0</publishTF>
      </plugin>
      <pose>-6.72908 1.75228 0 0 -0 0</pose>
    </model>
    <state world_name='default'>
      <sim_time>109 351000000</sim_time>
      <real_time>115 651233031</real_time>
      <wall_time>1666705995 685886242</wall_time>
      <iterations>109351</iterations>
      <model name='automobile'>
        <pose>-6.8712 1.73908 0.032943 1.9e-05 0.000402 1.57754</pose>
        <scale>1 1 1</scale>
        <link name='cam_birdeye_REC::link_camera'>
          <pose>-6.87118 1.73968 1.53294 3.09614 1.57043 -1.60951</pose>
          <velocity>0.000468 0.001157 0.000251 0.003015 -0.000773 0.000107</velocity>
          <acceleration>0.053804 -0.121558 0.26139 1.14725 -1.25784 -0.012275</acceleration>
          <wrench>5.4e-05 -0.000122 0.000261 0 -0 0</wrench>
        </link>
        <link name='camera::link_camera'>
          <pose>-6.87119 1.73916 0.232943 1.5e-05 0.262074 1.57754</pose>
          <velocity>-0.0002 -0.000398 0.000252 0.002573 -4.2e-05 0.000107</velocity>
          <acceleration>0.106324 -0.332018 0.261819 0.879823 -1.51916 -0.012212</acceleration>
          <wrench>0.000562 -0.001756 0.001384 0 -0 0</wrench>
        </link>
        <link name='camera_follow::link_camera'>
          <pose>-6.86917 1.43929 0.483037 1.7e-05 0.600418 1.57754</pose>
          <velocity>-0.000542 -0.000521 0.000978 0.003217 -0.000157 0.000301</velocity>
          <acceleration>0.094047 -0.813545 0.15075 1.04564 -1.20443 -0.126114</acceleration>
          <wrench>9.4e-05 -0.000814 0.000151 0 -0 0</wrench>
        </link>
        <link name='car_body::link'>
          <pose>-6.87104 1.71507 0.004952 1.8e-05 0.000398 1.57754</pose>
          <velocity>0.00013 -0.000351 0.000208 0.001881 -0.001151 0.000153</velocity>
          <acceleration>0.035411 -0.039377 0.223691 1.61708 0.268292 -0.022007</acceleration>
          <wrench>0.035411 -0.039377 0.223691 0 -0 0</wrench>
        </link>
        <link name='chassis::link'>
          <pose>-6.8712 1.73908 0.032943 0.000402 -1.9e-05 -3.13485</pose>
          <velocity>9.5e-05 -0.000405 0.000253 0.001913 -0.001356 0.000167</velocity>
          <acceleration>0.0442 -0.084793 0.262935 1.63076 0.419153 -0.024935</acceleration>
          <wrench>0.0116 -0.022253 0.069005 0 -0 0</wrench>
        </link>
        <link name='steer_left::link_steer'>
          <pose>-6.93888 1.84565 0.033036 1.57117 -6.6e-05 -3.02648</pose>
          <velocity>6.9e-05 -2.6e-05 -9.8e-05 0.001758 -0.000492 0.003461</velocity>
          <acceleration>0.102746 -0.019549 -0.143661 1.57758 -0.586866 2.0476</acceleration>
          <wrench>0.000103 -2e-05 -0.000144 0 -0 0</wrench>
        </link>
        <link name='steer_right::link_steer'>
          <pose>-6.79955 1.85057 0.03304 1.57072 0.000378 1.37671</pose>
          <velocity>9e-06 -0.000386 -3e-06 0.001943 -0.000793 -0.003109</velocity>
          <acceleration>-0.486965 -0.028269 0.156921 1.5698 -1.3369 0.584779</acceleration>
          <wrench>-0.000487 -2.8e-05 0.000157 0 -0 0</wrench>
        </link>
        <link name='wheel_front_left::link_rim'>
          <pose>-6.94386 1.83652 0.033003 1.57116 -0.927825 -3.02678</pose>
          <velocity>0.000105 -0.000117 -2.1e-05 0.003632 0.001728 0.003415</velocity>
          <acceleration>0.111147 -0.045268 -0.00025 1.55693 1.56123 -2.55564</acceleration>
          <wrench>0.004224 -0.00172 -9e-06 0 -0 0</wrench>
        </link>
        <link name='wheel_front_right::link_rim'>
          <pose>-6.79005 1.85481 0.033 1.5708 -0.547359 1.37671</pose>
          <velocity>1e-05 -0.000426 0.00016 0.012863 0.000311 -0.000843</velocity>
          <acceleration>-0.386644 -0.026544 0.243469 0.684804 0.821882 -1.05316</acceleration>
          <wrench>-0.014692 -0.001009 0.009252 0 -0 0</wrench>
        </link>
        <link name='wheel_rear_left::link_rim'>
          <pose>-6.95117 1.58654 0.033 1.57076 -0.579453 1.57756</pose>
          <velocity>6.1e-05 -0.000415 -1.2e-05 0.012682 0.001773 0.000229</velocity>
          <acceleration>0.034386 -0.084252 -0.0123 1.57374 1.00716 -0.043443</acceleration>
          <wrench>0.001307 -0.003202 -0.000467 0 -0 0</wrench>
        </link>
        <link name='wheel_rear_right::link_rim'>
          <pose>-6.78917 1.58763 0.033 1.57085 -0.248678 1.57752</pose>
          <velocity>9.3e-05 -0.000393 1.3e-05 0.011857 0.002792 0.000135</velocity>
          <acceleration>0.024073 -0.088063 0.027505 1.66397 0.690313 -0.065589</acceleration>
          <wrench>0.000915 -0.003346 0.001045 0 -0 0</wrench>
        </link>
      </model>
      <model name='track'>
        <pose>0 0 0 0 -0 0</pose>
        <scale>1 1 1</scale>
        <link name='link'>
          <pose>0 0 0 0 -0 0</pose>
          <velocity>0 0 0 0 -0 0</velocity>
          <acceleration>0 0 0 0 -0 0</acceleration>
          <wrench>0 0 0 0 -0 0</wrench>
        </link>
      </model>
      <light name='sun'>
        <pose>0 0 10 0 -0 0</pose>
      </light>
    </state>
    <gui fullscreen='0'>
      <camera name='user_camera'>
        <pose>-6.90021 -1.35074 0.665655 0 0.155643 1.3522</pose>
        <view_controller>orbit</view_controller>
        <projection_type>perspective</projection_type>
      </camera>
    </gui>
  </world>
</sdf>
